Workbook

Sheet Supuestos
A1: FLUJO DE FONDOS — FIDEICOMISO INMOBILIARIO
A2: Hoja de Supuestos y Parámetros del Modelo
A4: PARÁMETROS GENERALES DEL PROYECTO
A5: Mes de inicio de preventa (mes 1 = mes 1 del modelo) | B5: 1 | C5: La preventa arranca en el mes 1
A6: Mes de inicio de obra (mes del modelo) | B6: 9 | C6: Obra comienza mes 9 (8 meses de preventa)
A7: Duración de la obra (meses) | B7: 30 | C7: 30 meses de ejecución
A8: Mes de entrega / cierre del fideicomiso | B8: 42 | C8: Mes 9 inicio obra + 30 meses + 3 meses cierre
A9: Total de unidades del proyecto | B9: 80 | C9: Edificio de 80 unidades
A10: Superficie promedio por unidad (m²) | B10: 65 | C10: Mix 1, 2 y 3 ambientes
A11: Superficie total vendible (m²) — calculado | B11: =B9*B10 -> 5200 | C11: Total m² vendibles
A13: TERRENO E INVERSORES INICIALES
A14: Costo del terreno (USD) | B14: 500000 | C14: Inversor aporta 100% del terreno
A15: TIR objetivo del inversor de terreno (% anual) | B15: 0.12 | C15: Retorno mínimo exigido
A16: Mes de devolución al inversor de terreno | B16: 41 | C16: Previo al cierre del fideicomiso
A18: COSTOS DE CONSTRUCCIÓN Y DESARROLLO
A19: Costo de construcción por m² (USD) | B19: 750 | C19: Hard cost — materiales + mano de obra
A20: Costo total de construcción (USD) — calculado | B20: =B11*B19 -> 3900000 | C20: Superficie vendible x costo por m2
A21: Soft costs: honorarios arquitecto (% sobre construcción) | B21: 0.06 | C21: Diseño y dirección de obra
A22: Soft costs: permisos y habilitaciones (% sobre construcción) | B22: 0.025 | C22: Municipalidad y registros
A23: Soft costs: gerenciamiento de obra (% sobre construcción) | B23: 0.04 | C23: Inspector + coordinación interna
A24: Contingencia de obra (% sobre construcción) | B24: 0.12 | C24: Colchón ante imprevistos
A25: Distribución de egresos de obra | C25: Ver curva S — tabla en FF
A27: INVERSORES DE CAPITAL DE OBRA (50% INICIO DE OBRA)
A28: % del costo total de obra aportado por inversores | B28: 0.5 | C28: Aportan el 50% del costo de construcción
A29: TIR objetivo inversores de obra (% anual) | B29: 0.2 | C29: Retorno preferente sobre capital aportado
A30: Retorno preferente adicional sobre excedente (%) | B30: 0.3 | C30: % del excedente que va a inversores
A31: Mes de inicio de devolución a inversores de obra | B31: 39 | C31: Con las escrituraciones
A33: INGRESOS Y POLÍTICA DE VENTAS
A34: Precio de venta promedio por m² en preventa (USD) | B34: 1900 | C34: Precio de lanzamiento
A35: Precio de venta promedio por m² en obra (USD) | B35: 2300 | C35: Precio en etapa de construcción
A36: Precio de venta promedio por m² en entrega (USD) | B36: 2600 | C36: Precio al terminar obra
A37: Unidades en preventa (meses 1-8) | B37: 24 | C37: 30% del total en preventa
A38: Unidades vendidas durante obra (meses 9-38) | B38: 48 | C38: 60% durante obra
A39: Unidades vendidas en entrega / post-obra | B39: 8 | C39: 10% restante
A40: Estructura de cobro — reserva (% del precio) | B40: 0.03 | C40: Al firmar la reserva
A41: Estructura de cobro — cuotas durante obra (% precio) | B41: 0.87 | C41: En cuotas mensuales durante la obra
A42: Estructura de cobro — saldo escritura (% precio) | B42: 0.1 | C42: Al momento de escriturar
A43: Tasa de cancelación de boletos (% del total) | B43: 0.05 | C43: Rescisiones estimadas
A45: COSTOS DE MARKETING Y COMERCIALIZACIÓN
A46: Comisión canal de ventas interno (% sobre precio) | B46: 0.03 | C46: Equipo propio
...

Sheet Flujo de Fondos
A1: FLUJO DE FONDOS PROYECTADO — FIDEICOMISO INMOBILIARIO
A2: Moneda: USD | Modelo mensual | Supuestos editables en hoja 'Supuestos'
A3: CONCEPTO | B3: Unidad | C3: Mes 1 | D3: Mes 2 | E3: Mes 3 | F3: Mes 4 | G3: Mes 5 | H3: Mes 6 | I3: Mes 7 | J3: Mes 8 | K3: Mes 9 | L3: Mes 10 | M3: Mes 11 | N3: Mes 12 | O3: Mes 13 | P3: Mes 14 | Q3: Mes 15 | R3: Mes 16 | S3: Mes 17 | T3: Mes 18 | U3: Mes 19 | V3: Mes 20 | W3: Mes 21 | X3: Mes 22 | Y3: Mes 23 | Z3: Mes 24 | AA3: Mes 25 | AB3: Mes 26 | AC3: Mes 27 | AD3: Mes 28 | AE3: Mes 29 | AF3: Mes 30 | AG3: Mes 31 | AH3: Mes 32 | AI3: Mes 33 | AJ3: Mes 34 | AK3: Mes 35 | AL3: Mes 36 | AM3: Mes 37 | AN3: Mes 38 | AO3: Mes 39 | AP3: Mes 40 | AQ3: Mes 41 | AR3: Mes 42 | AS3: Mes 43 | AT3: Mes 44 | AU3: TOTAL
A4: Etapa del proyecto | C4: PREVENTA | D4: PREVENTA | E4: PREVENTA | F4: PREVENTA | G4: PREVENTA | H4: PREVENTA | I4: PREVENTA | J4: PREVENTA | K4: CONSTRUCCIÓN | L4: CONSTRUCCIÓN | M4: CONSTRUCCIÓN | N4: CONSTRUCCIÓN | O4: CONSTRUCCIÓN | P4: CONSTRUCCIÓN | Q4: CONSTRUCCIÓN | R4: CONSTRUCCIÓN | S4: CONSTRUCCIÓN | T4: CONSTRUCCIÓN | U4: CONSTRUCCIÓN | V4: CONSTRUCCIÓN | W4: CONSTRUCCIÓN | X4: CONSTRUCCIÓN | Y4: CONSTRUCCIÓN | Z4: CONSTRUCCIÓN | AA4: CONSTRUCCIÓN | AB4: CONSTRUCCIÓN | AC4: CONSTRUCCIÓN | AD4: CONSTRUCCIÓN | AE4: CONSTRUCCIÓN | AF4: CONSTRUCCIÓN | AG4: CONSTRUCCIÓN | AH4: CONSTRUCCIÓN | AI4: CONSTRUCCIÓN | AJ4: CONSTRUCCIÓN | AK4: CONSTRUCCIÓN | AL4: CONSTRUCCIÓN | AM4: CONSTRUCCIÓN | AN4: CONSTRUCCIÓN | AO4: ENTREGA | AP4: ENTREGA | AQ4: ENTREGA | AR4: CIERRE | AS4: CIERRE | AT4: CIERRE
A5: A. INGRESOS
A6: A1. Reservas — preventa (meses 1-8) | B6: USD | C6: =(Supuestos!B37/8)*Supuestos!B10*Supuestos!B34*Supuestos!B40 -> 11115 | D6: =(Supuestos!B37/8)*Supuestos!B10*Supuestos!B34*Supuestos!B40 -> 11115 | E6: =(Supuestos!B37/8)*Supuestos!B10*Supuestos!B34*Supuestos!B40 -> 11115 | F6: =(Supuestos!B37/8)*Supuestos!B10*Supuestos!B34*Supuestos!B40 -> 11115 | G6: =(Supuestos!B37/8)*Supuestos!B10*Supuestos!B34*Supuestos!B40 -> 11115 | H6: =(Supuestos!B37/8)*Supuestos!B10*Supuestos!B34*Supuestos!B40 -> 11115 | I6: =(Supuestos!B37/8)*Supuestos!B10*Supuestos!B34*Supuestos!B40 -> 11115 | J6: =(Supuestos!B37/8)*Supuestos!B10*Supuestos!B34*Supuestos!B40 -> 11115 | K6: 0 | L6: 0 | M6: 0 | N6: 0 | O6: 0 | P6: 0 | Q6: 0 | R6: 0 | S6: 0 | T6: 0 | U6: 0 | V6: 0 | W6: 0 | X6: 0 | Y6: 0 | Z6: 0 | AA6: 0 | AB6: 0 | AC6: 0 | AD6: 0 | AE6: 0 | AF6: 0 | AG6: 0 | AH6: 0 | AI6: 0 | AJ6: 0 | AK6: 0 | AL6: 0 | AM6: 0 | AN6: 0 | AO6: 0 | AP6: 0 | AQ6: 0 | AR6: 0 | AS6: 0 | AT6: 0 | AU6: =SUM(C6:AT6) -> 88920
A7: A2. Cuotas en obra — unidades en preventa | B7: USD | C7: 0 | D7: 0 | E7: 0 | F7: 0 | G7: 0 | H7: 0 | I7: 0 | J7: 0 | K7: =(Supuestos!B37*Supuestos!B10*Supuestos!B34*Supuestos!B41)/30 -> 85956 | L7: =(Supuestos!B37*Supuestos!B10*Supuestos!B34*Supuestos!B41)/30 -> 85956 | M7: =(Supuestos!B37*Supuestos!B10*Supuestos!B34*Supuestos!B41)/30 -> 85956 | N7: =(Supuestos!B37*Supuestos!B10*Supuestos!B34*Supuestos!B41)/30 -> 85956 | O7: =(Supuestos!B37*Supuestos!B10*Supuestos!B34*Supuestos!B41)/30 -> 85956 | P7: =(Supuestos!B37*Supuestos!B10*Supuestos!B34*Supuestos!B41)/30 -> 85956 | Q7: =(Supuestos!B37*Supuestos!B10*Supuestos!B34*Supuestos!B41)/30 -> 85956 | R7: =(Supuestos!B37*Supuestos!B10*Supuestos!B34*Supuestos!B41)/30 -> 85956 | S7: =(Supuestos!B37*Supuestos!B10*Supuestos!B34*Supuestos!B41)/30 -> 85956 | T7: =(Supuestos!B37*Supuestos!B10*Supuestos!B34*Supuestos!B41)/30 -> 85956 | U7: =(Supuestos!B37*Supuestos!B10*Supuestos!B34*Supuestos!B41)/30 -> 85956 | V7: =(Supuestos!B37*Supuestos!B10*Supuestos!B34*Supuestos!B41)/30 -> 85956 | W7: =(Supuestos!B37*Supuestos!B10*Supuestos!B34*Supuestos!B41)/30 -> 85956 | X7: =(Supuestos!B37*Supuestos!B10*Supuestos!B34*Supuestos!B41)/30 -> 85956 | Y7: =(Supuestos!B37*Supuestos!B10*Supuestos!B34*Supuestos!B41)/30 -> 85956 | Z7: =(Supuestos!B37*Supuestos!B10*Supuestos!B34*Supuestos!B41)/30 -> 85956 | AA7: =(Supuestos!B37*Supuestos!B10*Supuestos!B34*Supuestos!B41)/30 -> 85956 | AB7: =(Supuestos!B37*Supuestos!B10*Supuestos!B34*Supuestos!B41)/30 -> 85956 | AC7: =(Supuestos!B37*Supuestos!B10*Supuestos!B34*Supuestos!B41)/30 -> 85956 | AD7: =(Supuestos!B37*Supuestos!B10*Supuestos!B34*Supuestos!B41)/30 -> 85956 | AE7: =(Supuestos!B37*Supuestos!B10*Supuestos!B34*Supuestos!B41)/30 -> 85956 | AF7: =(Supuestos!B37*Supuestos!B10*Supuestos!B34*Supuestos!B41)/30 -> 85956 | AG7: =(Supuestos!B37*Supuestos!B10*Supuestos!B34*Supuestos!B41)/30 -> 85956 | AH7: =(Supuestos!B37*Supuestos!B10*Supuestos!B34*Supuestos!B41)/30 -> 85956 | AI7: =(Supuestos!B37*Supuestos!B10*Supuestos!B34*Supuestos!B41)/30 -> 85956 | AJ7: =(Supuestos!B37*Supuestos!B10*Supuestos!B34*Supuestos!B41)/30 -> 85956 | AK7: =(Supuestos!B37*Supuestos!B10*Supuestos!B34*Supuestos!B41)/30 -> 85956 | AL7: =(Supuestos!B37*Supuestos!B10*Supuestos!B34*Supuestos!B41)/30 -> 85956 | AM7: =(Supuestos!B37*Supuestos!B10*Supuestos!B34*Supuestos!B41)/30 -> 85956 | AN7: =(Supuestos!B37*Supuestos!B10*Supuestos!B34*Supuestos!B41)/30 -> 85956 | AO7: 0 | AP7: 0 | AQ7: 0 | AR7: 0 | AS7: 0 | AT7: 0 | AU7: =SUM(C7:AT7) -> 2578680
A8: A3. Reservas — unidades vendidas en obra | B8: USD | C8: 0 | D8: 0 | E8: 0 | F8: 0 | G8: 0 | H8: 0 | I8: 0 | J8: 0 | K8: =(Supuestos!B38/30)*Supuestos!B10*Supuestos!B35*Supuestos!B40 -> 7176 | L8: =(Supuestos!B38/30)*Supuestos!B10*Supuestos!B35*Supuestos!B40 -> 7176 | M8: =(Supuestos!B38/30)*Supuestos!B10*Supuestos!B35*Supuestos!B40 -> 7176 | N8: =(Supuestos!B38/30)*Supuestos!B10*Supuestos!B35*Supuestos!B40 -> 7176 | O8: =(Supuestos!B38/30)*Supuestos!B10*Supuestos!B35*Supuestos!B40 -> 7176 | P8: =(Supuestos!B38/30)*Supuestos!B10*Supuestos!B35*Supuestos!B40 -> 7176 | Q8: =(Supuestos!B38/30)*Supuestos!B10*Supuestos!B35*Supuestos!B40 -> 7176 | R8: =(Supuestos!B38/30)*Supuestos!B10*Supuestos!B35*Supuestos!B40 -> 7176 | S8: =(Supuestos!B38/30)*Supuestos!B10*Supuestos!B35*Supuestos!B40 -> 7176 | T8: =(Supuestos!B38/30)*Supuestos!B10*Supuestos!B35*Supuestos!B40 -> 7176 | U8: =(Supuestos!B38/30)*Supuestos!B10*Supuestos!B35*Supuestos!B40 -> 7176 | V8: =(Supuestos!B38/30)*Supuestos!B10*Supuestos!B35*Supuestos!B40 -> 7176 | W8: =(Supuestos!B38/30)*Supuestos!B10*Supuestos!B35*Supuestos!B40 -> 7176 | X8: =(Supuestos!B38/30)*Supuestos!B10*Supuestos!B35*Supuestos!B40 -> 7176 | Y8: =(Supuestos!B38/30)*Supuestos!B10*Supuestos!B35*Supuestos!B40 -> 7176 | Z8: =(Supuestos!B38/30)*Supuestos!B10*Supuestos!B35*Supuestos!B40 -> 7176 | AA8: =(Supuestos!B38/30)*Supuestos!B10*Supuestos!B35*Supuestos!B40 -> 7176 | AB8: =(Supuestos!B38/30)*Supuestos!B10*Supuestos!B35*Supuestos!B40 -> 7176 | AC8: =(Supuestos!B38/30)*Supuestos!B10*Supuestos!B35*Supuestos!B40 -> 7176 | AD8: =(Supuestos!B38/30)*Supuestos!B10*Supuestos!B35*Supuestos!B40 -> 7176 | AE8: =(Supuestos!B38/30)*Supuestos!B10*Supuestos!B35*Supuestos!B40 -> 7176 | AF8: =(Supuestos!B38/30)*Supuestos!B10*Supuestos!B35*Supuestos!B40 -> 7176 | AG8: =(Supuestos!B38/30)*Supuestos!B10*Supuestos!B35*Supuestos!B40 -> 7176 | AH8: =(Supuestos!B38/30)*Supuestos!B10*Supuestos!B35*Supuestos!B40 -> 7176 | AI8: =(Supuestos!B38/30)*Supuestos!B10*Supuestos!B35*Supuestos!B40 -> 7176 | AJ8: =(Supuestos!B38/30)*Supuestos!B10*Supuestos!B35*Supuestos!B40 -> 7176 | AK8: =(Supuestos!B38/30)*Supuestos!B10*Supuestos!B35*Supuestos!B40 -> 7176 | AL8: =(Supuestos!B38/30)*Supuestos!B10*Supuestos!B35*Supuestos!B40 -> 7176 | AM8: =(Supuestos!B38/30)*Supuestos!B10*Supuestos!B35*Supuestos!B40 -> 7176 | AN8: =(Supuestos!B38/30)*Supuestos!B10*Supuestos!B35*Supuestos!B40 -> 7176 | AO8: 0 | AP8: 0 | AQ8: 0 | AR8: 0 | AS8: 0 | AT8: 0 | AU8: =SUM(C8:AT8) -> 215280
A9: A4. Cuotas en obra — unidades vendidas en obra | B9: USD | C9: 0 | D9: 0 | E9: 0 | F9: 0 | G9: 0 | H9: 0 | I9: 0 | J9: 0 | K9: 0 | L9: =(Supuestos!B38/30)*Supuestos!B10*Supuestos!B35*Supuestos!B41/15 -> 13873.6 | M9: =(Supuestos!B38/30)*Supuestos!B10*Supuestos!B35*Supuestos!B41/15 -> 13873.6 | N9: =(Supuestos!B38/30)*Supuestos!B10*Supuestos!B35*Supuestos!B41/15 -> 13873.6 | O9: =(Supuestos!B38/30)*Supuestos!B10*Supuestos!B35*Supuestos!B41/15 -> 13873.6 | P9: =(Supuestos!B38/30)*Supuestos!B10*Supuestos!B35*Supuestos!B41/15 -> 13873.6 | Q9: =(Supuestos!B38/30)*Supuestos!B10*Supuestos!B35*Supuestos!B41/15 -> 13873.6 | R9: =(Supuestos!B38/30)*Supuestos!B10*Supuestos!B35*Supuestos!B41/15 -> 13873.6 | S9: =(Supuestos!B38/30)*Supuestos!B10*Supuestos!B35*Supuestos!B41/15 -> 13873.6 | T9: =(Supuestos!B38/30)*Supuestos!B10*Supuestos!B35*Supuestos!B41/15 -> 13873.6 | U9: =(Supuestos!B38/30)*Supuestos!B10*Supuestos!B35*Supuestos!B41/15 -> 13873.6 | V9: =(Supuestos!B38/30)*Supuestos!B10*Supuestos!B35*Supuestos!B41/15 -> 13873.6 | W9: =(Supuestos!B38/30)*Supuestos!B10*Supuestos!B35*Supuestos!B41/15 -> 13873.6 | X9: =(Supuestos!B38/30)*Supuestos!B10*Supuestos!B35*Supuestos!B41/15 -> 13873.6 | Y9: =(Supuestos!B38/30)*Supuestos!B10*Supuestos!B35*Supuestos!B41/15 -> 13873.6 | Z9: =(Supuestos!B38/30)*Supuestos!B10*Supuestos!B35*Supuestos!B41/15 -> 13873.6 | AA9: =(Supuestos!B38/30)*Supuestos!B10*Supuestos!B35*Supuestos!B41/15 -> 13873.6 | AB9: =(Supuestos!B38/30)*Supuestos!B10*Supuestos!B35*Supuestos!B41/15 -> 13873.6 | AC9: =(Supuestos!B38/30)*Supuestos!B10*Supuestos!B35*Supuestos!B41/15 -> 13873.6 | AD9: =(Supuestos!B38/30)*Supuestos!B10*Supuestos!B35*Supuestos!B41/15 -> 13873.6 | AE9: =(Supuestos!B38/30)*Supuestos!B10*Supuestos!B35*Supuestos!B41/15 -> 13873.6 | AF9: =(Supuestos!B38/30)*Supuestos!B10*Supuestos!B35*Supuestos!B41/15 -> 13873.6 | AG9: =(Supuestos!B38/30)*Supuestos!B10*Supuestos!B35*Supuestos!B41/15 -> 13873.6 | AH9: =(Supuestos!B38/30)*Supuestos!B10*Supuestos!B35*Supuestos!B41/15 -> 13873.6 | AI9: =(Supuestos!B38/30)*Supuestos!B10*Supuestos!B35*Supuestos!B41/15 -> 13873.6 | AJ9: =(Supuestos!B38/30)*Supuestos!B10*Supuestos!B35*Supuestos!B41/15 -> 13873.6 | AK9: =(Supuestos!B38/30)*Supuestos!B10*Supuestos!B35*Supuestos!B41/15 -> 13873.6 | AL9: =(Supuestos!B38/30)*Supuestos!B10*Supuestos!B35*Supuestos!B41/15 -> 13873.6 | AM9: =(Supuestos!B38/30)*Supuestos!B10*Supuestos!B35*Supuestos!B41/15 -> 13873.6 | AN9: =(Supuestos!B38/30)*Supuestos!B10*Supuestos!B35*Supuestos!B41/15 -> 13873.6 | AO9: 0 | AP9: 0 | AQ9: 0 | AR9: 0 | AS9: 0 | AT9: 0 | AU9: =SUM(C9:AT9) -> 402334.4
A10: A5. Saldo escrituración — unidades preventa | B10: USD | C10: 0 | D10: 0 | E10: 0 | F10: 0 | G10: 0 | H10: 0 | I10: 0 | J10: 0 | K10: 0 | L10: 0 | M10: 0 | N10: 0 | O10: 0 | P10: 0 | Q10: 0 | R10: 0 | S10: 0 | T10: 0 | U10: 0 | V10: 0 | W10: 0 | X10: 0 | Y10: 0 | Z10: 0 | AA10: 0 | AB10: 0 | AC10: 0 | AD10: 0 | AE10: 0 | AF10: 0 | AG10: 0 | AH10: 0 | AI10: 0 | AJ10: 0 | AK10: 0 | AL10: 0 | AM10: 0 | AN10: 0 | AO10: =(Supuestos!B37/3)*Supuestos!B10*Supuestos!B34*Supuestos!B42*(1-Supuestos!B43) -> 93860 | AP10: =(Supuestos!B37/3)*Supuestos!B10*Supuestos!B34*Supuestos!B42*(1-Supuestos!B43) -> 93860 | AQ10: =(Supuestos!B37/3)*Supuestos!B10*Supuestos!B34*Supuestos!B42*(1-Supuestos!B43) -> 93860 | AR10: 0 | AS10: 0 | AT10: 0 | AU10: =SUM(C10:AT10) -> 281580
A11: A6. Saldo escrituración — unidades vendidas en obra | B11: USD | C11: 0 | D11: 0 | E11: 0 | F11: 0 | G11: 0 | H11: 0 | I11: 0 | J11: 0 | K11: 0 | L11: 0 | M11: 0 | N11: 0 | O11: 0 | P11: 0 | Q11: 0 | R11: 0 | S11: 0 | T11: 0 | U11: 0 | V11: 0 | W11: 0 | X11: 0 | Y11: 0 | Z11: 0 | AA11: 0 | AB11: 0 | AC11: 0 | AD11: 0 | AE11: 0 | AF11: 0 | AG11: 0 | AH11: 0 | AI11: 0 | AJ11: 0 | AK11: 0 | AL11: 0 | AM11: 0 | AN11: 0 | AO11: =(Supuestos!B38/5)*Supuestos!B10*Supuestos!B35*Supuestos!B42*(1-Supuestos!B43) -> 136344 | AP11: =(Supuestos!B38/5)*Supuestos!B10*Supuestos!B35*Supuestos!B42*(1-Supuestos!B43) -> 136344 | AQ11: =(Supuestos!B38/5)*Supuestos!B10*Supuestos!B35*Supuestos!B42*(1-Supuestos!B43) -> 136344 | AR11: =(Supuestos!B38/5)*Supuestos!B10*Supuestos!B35*Supuestos!B42*(1-Supuestos!B43) -> 136344 | AS11: =(Supuestos!B38/5)*Supuestos!B10*Supuestos!B35*Supuestos!B42*(1-Supuestos!B43) -> 136344 | AT11: 0 | AU11: =SUM(C11:AT11) -> 681720
A12: A7. Ventas y escrituración — unidades post-obra | B12: USD | C12: 0 | D12: 0 | E12: 0 | F12: 0 | G12: 0 | H12: 0 | I12: 0 | J12: 0 | K12: 0 | L12: 0 | M12: 0 | N12: 0 | O12: 0 | P12: 0 | Q12: 0 | R12: 0 | S12: 0 | T12: 0 | U12: 0 | V12: 0 | W12: 0 | X12: 0 | Y12: 0 | Z12: 0 | AA12: 0 | AB12: 0 | AC12: 0 | AD12: 0 | AE12: 0 | AF12: 0 | AG12: 0 | AH12: 0 | AI12: 0 | AJ12: 0 | AK12: 0 | AL12: 0 | AM12: 0 | AN12: 0 | AO12: 0 | AP12: =(Supuestos!B39/5)*Supuestos!B10*Supuestos!B36*(1-Supuestos!B43) -> 256880 | AQ12: =(Supuestos!B39/5)*Supuestos!B10*Supuestos!B36*(1-Supuestos!B43) -> 256880 | AR12: =(Supuestos!B39/5)*Supuestos!B10*Supuestos!B36*(1-Supuestos!B43) -> 256880 | AS12: =(Supuestos!B39/5)*Supuestos!B10*Supuestos!B36*(1-Supuestos!B43) -> 256880 | AT12: =(Supuestos!B39/5)*Supuestos!B10*Supuestos!B36*(1-Supuestos!B43) -> 256880 | AU12: =SUM(C12:AT12) -> 1284400
A13: SUBTOTAL INGRESOS BRUTOS | B13: USD | C13: =SUM(C6:C12) -> 11115 | D13: =SUM(D6:D12) -> 11115 | E13: =SUM(E6:E12) -> 11115 | F13: =SUM(F6:F12) -> 11115 | G13: =SUM(G6:G12) -> 11115 | H13: =SUM(H6:H12) -> 11115 | I13: =SUM(I6:I12) -> 11115 | J13: =SUM(J6:J12) -> 11115 | ... AT13: =SUM(AT6:AT12) -> 256880 | AU13: =SUM(C13:AT13) -> 5532914.4
A14: B. EGRESOS — INVERSIÓN INICIAL (TERRENO E INICIO)
A15: B1. Compra del terreno (aportado por inversor) | B15: USD | C15: =-Supuestos!B14 -> -500000 | D15: 0 | E15: 0 | F15: 0 | G15: 0 | H15: 0 | I15: 0 | J15: 0 | K15: 0 | L15: 0 | M15: 0 | N15: 0 | O15: 0 | P15: 0 | Q15: 0 | R15: 0 | S15: 0 | T15: 0 | U15: 0 | V15: 0 | W15: 0 | X15: 0 | Y15: 0 | Z15: 0 | AA15: 0 | AB15: 0 | AC15: 0 | AD15: 0 | AE15: 0 | AF15: 0 | AG15: 0 | AH15: 0 | AI15: 0 | AJ15: 0 | AK15: 0 | AL15: 0 | AM15: 0 | AN15: 0 | AO15: 0 | AP15: 0 | AQ15: 0 | AR15: 0 | AS15: 0 | AT15: 0 | AU15: =SUM(C15:AT15) -> -500000
A16: B2. Due diligence, estudios y gastos previos | B16: USD | C16: =-Supuestos!B14*0.015 -> -7500 | D16: 0 | E16: 0 | F16: 0 | G16: 0 | H16: 0 | I16: 0 | J16: 0 | K16: 0 | L16: 0 | M16: 0 | N16: 0 | O16: 0 | P16: 0 | Q16: 0 | R16: 0 | S16: 0 | T16: 0 | U16: 0 | V16: 0 | W16: 0 | X16: 0 | Y16: 0 | Z16: 0 | AA16: 0 | AB16: 0 | AC16: 0 | AD16: 0 | AE16: 0 | AF16: 0 | AG16: 0 | AH16: 0 | AI16: 0 | AJ16: 0 | AK16: 0 | AL16: 0 | AM16: 0 | AN16: 0 | AO16: 0 | AP16: 0 | AQ16: 0 | AR16: 0 | AS16: 0 | AT16: 0 | AU16: =SUM(C16:AT16) -> -7500
A17: B3. Aporte inversores de obra (50% costo construcción, mes 9) | B17: USD | C17: 0 | D17: 0 | E17: 0 | F17: 0 | G17: 0 | H17: 0 | I17: 0 | J17: 0 | K17: 0 | L17: 0 | M17: 0 | N17: 0 | O17: 0 | P17: 0 | Q17: 0 | R17: 0 | S17: 0 | T17: 0 | U17: 0 | V17: 0 | W17: 0 | X17: 0 | Y17: 0 | Z17: 0 | AA17: 0 | AB17: 0 | AC17: 0 | AD17: 0 | AE17: 0 | AF17: 0 | AG17: 0 | AH17: 0 | AI17: 0 | AJ17: 0 | AK17: 0 | AL17: 0 | AM17: 0 | AN17: 0 | AO17: 0 | AP17: 0 | AQ17: 0 | AR17: 0 | AS17: 0 | AT17: 0 | AU17: =SUM(C17:AT17) -> 0
A18: SUBTOTAL EGRESOS INVERSIÓN INICIAL | B18: USD | C18: =SUM(C15:C17) -> -507500 | D18: =SUM(D15:D17) -> 0 | E18: =SUM(E15:E17) -> 0 | F18: =SUM(F15:F17) -> 0 | G18: =SUM(G15:G17) -> 0 | H18: =SUM(H15:H17) -> 0 | I18: =SUM(I15:I17) -> 0 | J18: =SUM(J15:J17) -> 0 | ... AT18: =SUM(AT15:AT17) -> 0 | AU18: =SUM(C18:AT18) -> -507500
A19: C. EGRESOS — CONSTRUCCIÓN Y OBRA (CURVA S)
A20: C1. Costo de construcción (hard cost — curva S) | B20: USD | C20: 0 | D20: 0 | E20: 0 | F20: 0 | G20: 0 | H20: 0 | I20: 0 | J20: 0 | K20: =-Supuestos!B20*0.010811 -> -42162.9 | L20: =-Supuestos!B20*0.016216 -> -63242.4 | M20: =-Supuestos!B20*0.021622 -> -84325.8 | N20: =-Supuestos!B20*0.032432 -> -126484.8 | O20: =-Supuestos!B20*0.037838 -> -147568.2 | P20: =-Supuestos!B20*0.043243 -> -168647.7 | Q20: =-Supuestos!B20*0.048649 -> -189731.1 | R20: =-Supuestos!B20*0.054054 -> -210810.6 | S20: =-Supuestos!B20*0.054054 -> -210810.6 | T20: =-Supuestos!B20*0.054054 -> -210810.6 | U20: =-Supuestos!B20*0.048649 -> -189731.1 | V20: =-Supuestos!B20*0.048649 -> -189731.1 | W20: =-Supuestos!B20*0.043243 -> -168647.7 | X20: =-Supuestos!B20*0.043243 -> -168647.7 | Y20: =-Supuestos!B20*0.037838 -> -147568.2 | Z20: =-Supuestos!B20*0.037838 -> -147568.2 | AA20: =-Supuestos!B20*0.037838 -> -147568.2 | AB20: =-Supuestos!B20*0.037838 -> -147568.2 | AC20: =-Supuestos!B20*0.032432 -> -126484.8 | AD20: =-Supuestos!B20*0.032432 -> -126484.8 | AE20: =-Supuestos!B20*0.032432 -> -126484.8 | AF20: =-Supuestos!B20*0.027027 -> -105405.3 | AG20: =-Supuestos!B20*0.027027 -> -105405.3 | AH20: =-Supuestos!B20*0.027027 -> -105405.3 | AI20: =-Supuestos!B20*0.027027 -> -105405.3 | AJ20: =-Supuestos!B20*0.021622 -> -84325.8 | AK20: =-Supuestos!B20*0.021622 -> -84325.8 | AL20: =-Supuestos!B20*0.016216 -> -63242.4 | AM20: =-Supuestos!B20*0.016216 -> -63242.4 | AN20: =-Supuestos!B20*0.010811 -> -42162.9 | AO20: 0 | AP20: 0 | AQ20: 0 | AR20: 0 | AS20: 0 | AT20: 0 | AU20: =SUM(C20:AT20) -> -3900000
A21: C2. Honorarios arquitecto y dirección de obra | B21: USD | C21: =-Supuestos!B20*Supuestos!B21*0.3/8 -> -8775 | D21: =-Supuestos!B20*Supuestos!B21*0.3/8 -> -8775 | E21: =-Supuestos!B20*Supuestos!B21*0.3/8 -> -8775 | F21: =-Supuestos!B20*Supuestos!B21*0.3/8 -> -8775 | G21: =-Supuestos!B20*Supuestos!B21*0.3/8 -> -8775 | H21: =-Supuestos!B20*Supuestos!B21*0.3/8 -> -8775 | I21: =-Supuestos!B20*Supuestos!B21*0.3/8 -> -8775 | J21: =-Supuestos!B20*Supuestos!B21*0.3/8 -> -8775 | K21: =-Supuestos!B20*Supuestos!B21*0.6/30 -> -4680 | L21: =-Supuestos!B20*Supuestos!B21*0.6/30 -> -4680 | M21: =-Supuestos!B20*Supuestos!B21*0.6/30 -> -4680 | N21: =-Supuestos!B20*Supuestos!B21*0.6/30 -> -4680 | O21: =-Supuestos!B20*Supuestos!B21*0.6/30 -> -4680 | P21: =-Supuestos!B20*Supuestos!B21*0.6/30 -> -4680 | Q21: =-Supuestos!B20*Supuestos!B21*0.6/30 -> -4680 | R21: =-Supuestos!B20*Supuestos!B21*0.6/30 -> -4680 | S21: =-Supuestos!B20*Supuestos!B21*0.6/30 -> -4680 | T21: =-Supuestos!B20*Supuestos!B21*0.6/30 -> -4680 | U21: =-Supuestos!B20*Supuestos!B21*0.6/30 -> -4680 | V21: =-Supuestos!B20*Supuestos!B21*0.6/30 -> -4680 | W21: =-Supuestos!B20*Supuestos!B21*0.6/30 -> -4680 | X21: =-Supuestos!B20*Supuestos!B21*0.6/30 -> -4680 | Y21: =-Supuestos!B20*Supuestos!B21*0.6/30 -> -4680 | Z21: =-Supuestos!B20*Supuestos!B21*0.6/30 -> -4680 | AA21: =-Supuestos!B20*Supuestos!B21*0.6/30 -> -4680 | AB21: =-Supuestos!B20*Supuestos!B21*0.6/30 -> -4680 | AC21: =-Supuestos!B20*Supuestos!B21*0.6/30 -> -4680 | AD21: =-Supuestos!B20*Supuestos!B21*0.6/30 -> -4680 | AE21: =-Supuestos!B20*Supuestos!B21*0.6/30 -> -4680 | AF21: =-Supuestos!B20*Supuestos!B21*0.6/30 -> -4680 | AG21: =-Supuestos!B20*Supuestos!B21*0.6/30 -> -4680 | AH21: =-Supuestos!B20*Supuestos!B21*0.6/30 -> -4680 | AI21: =-Supuestos!B20*Supuestos!B21*0.6/30 -> -4680 | AJ21: =-Supuestos!B20*Supuestos!B21*0.6/30 -> -4680 | AK21: =-Supuestos!B20*Supuestos!B21*0.6/30 -> -4680 | AL21: =-Supuestos!B20*Supuestos!B21*0.6/30 -> -4680 | AM21: =-Supuestos!B20*Supuestos!B21*0.6/30 -> -4680 | AN21: =-Supuestos!B20*Supuestos!B21*0.6/30 -> -4680 | AO21: =-Supuestos!B20*Supuestos!B21*0.1 -> -23400 | AP21: 0 | AQ21: 0 | AR21: 0 | AS21: 0 | AT21: 0 | AU21: =SUM(C21:AT21) -> -234000
A22: C3. Permisos, visados y habilitaciones municipales | B22: USD | C22: 0 | D22: 0 | E22: 0 | F22: 0 | G22: =-Supuestos!B20*Supuestos!B22*0.5 -> -48750 | H22: 0 | I22: 0 | J22: 0 | K22: 0 | L22: 0 | M22: 0 | N22: 0 | O22: 0 | P22: 0 | Q22: 0 | R22: 0 | S22: 0 | T22: 0 | U22: 0 | V22: 0 | W22: 0 | X22: 0 | Y22: 0 | Z22: 0 | AA22: 0 | AB22: 0 | AC22: 0 | AD22: 0 | AE22: 0 | AF22: 0 | AG22: 0 | AH22: 0 | AI22: 0 | AJ22: 0 | AK22: 0 | AL22: 0 | AM22: 0 | AN22: 0 | AO22: =-Supuestos!B20*Supuestos!B22*0.5 -> -48750 | AP22: 0 | AQ22: 0 | AR22: 0 | AS22: 0 | AT22: 0 | AU22: =SUM(C22:AT22) -> -97500
A23: C4. Gerenciamiento e inspección de obra | B23: USD | C23: 0 | D23: 0 | E23: 0 | F23: 0 | G23: 0 | H23: 0 | I23: 0 | J23: 0 | K23: =-Supuestos!B20*Supuestos!B23/30 -> -5200 | L23: =-Supuestos!B20*Supuestos!B23/30 -> -5200 | M23: =-Supuestos!B20*Supuestos!B23/30 -> -5200 | N23: =-Supuestos!B20*Supuestos!B23/30 -> -5200 | O23: =-Supuestos!B20*Supuestos!B23/30 -> -5200 | P23: =-Supuestos!B20*Supuestos!B23/30 -> -5200 | Q23: =-Supuestos!B20*Supuestos!B23/30 -> -5200 | R23: =-Supuestos!B20*Supuestos!B23/30 -> -5200 | S23: =-Supuestos!B20*Supuestos!B23/30 -> -5200 | T23: =-Supuestos!B20*Supuestos!B23/30 -> -5200 | U23: =-Supuestos!B20*Supuestos!B23/30 -> -5200 | V23: =-Supuestos!B20*Supuestos!B23/30 -> -5200 | W23: =-Supuestos!B20*Supuestos!B23/30 -> -5200 | X23: =-Supuestos!B20*Supuestos!B23/30 -> -5200 | Y23: =-Supuestos!B20*Supuestos!B23/30 -> -5200 | Z23: =-Supuestos!B20*Supuestos!B23/30 -> -5200 | AA23: =-Supuestos!B20*Supuestos!B23/30 -> -5200 | AB23: =-Supuestos!B20*Supuestos!B23/30 -> -5200 | AC23: =-Supuestos!B20*Supuestos!B23/30 -> -5200 | AD23: =-Supuestos!B20*Supuestos!B23/30 -> -5200 | AE23: =-Supuestos!B20*Supuestos!B23/30 -> -5200 | AF23: =-Supuestos!B20*Supuestos!B23/30 -> -5200 | AG23: =-Supuestos!B20*Supuestos!B23/30 -> -5200 | AH23: =-Supuestos!B20*Supuestos!B23/30 -> -5200 | AI23: =-Supuestos!B20*Supuestos!B23/30 -> -5200 | AJ23: =-Supuestos!B20*Supuestos!B23/30 -> -5200 | AK23: =-Supuestos!B20*Supuestos!B23/30 -> -5200 | AL23: =-Supuestos!B20*Supuestos!B23/30 -> -5200 | AM23: =-Supuestos!B20*Supuestos!B23/30 -> -5200 | AN23: =-Supuestos!B20*Supuestos!B23/30 -> -5200 | AO23: 0 | AP23: 0 | AQ23: 0 | AR23: 0 | AS23: 0 | AT23: 0 | AU23: =SUM(C23:AT23) -> -156000
A24: C5. Contingencia de obra (colchón imprevistos) | B24: USD | C24: 0 | D24: 0 | E24: 0 | F24: 0 | G24: 0 | H24: 0 | I24: 0 | J24: 0 | K24: =-Supuestos!B20*Supuestos!B24*0.010811 -> -5059.548 | L24: =-Supuestos!B20*Supuestos!B24*0.016216 -> -7589.088 | M24: =-Supuestos!B20*Supuestos!B24*0.021622 -> -10119.096 | N24: =-Supuestos!B20*Supuestos!B24*0.032432 -> -15178.176 | O24: =-Supuestos!B20*Supuestos!B24*0.037838 -> -17708.184 | P24: =-Supuestos!B20*Supuestos!B24*0.043243 -> -20237.724 | Q24: =-Supuestos!B20*Supuestos!B24*0.048649 -> -22767.732 | R24: =-Supuestos!B20*Supuestos!B24*0.054054 -> -25297.272 | S24: =-Supuestos!B20*Supuestos!B24*0.054054 -> -25297.272 | T24: =-Supuestos!B20*Supuestos!B24*0.054054 -> -25297.272 | U24: =-Supuestos!B20*Supuestos!B24*0.048649 -> -22767.732 | V24: =-Supuestos!B20*Supuestos!B24*0.048649 -> -22767.732 | W24: =-Supuestos!B20*Supuestos!B24*0.043243 -> -20237.724 | X24: =-Supuestos!B20*Supuestos!B24*0.043243 -> -20237.724 | Y24: =-Supuestos!B20*Supuestos!B24*0.037838 -> -17708.184 | Z24: =-Supuestos!B20*Supuestos!B24*0.037838 -> -17708.184 | AA24: =-Supuestos!B20*Supuestos!B24*0.037838 -> -17708.184 | AB24: =-Supuestos!B20*Supuestos!B24*0.037838 -> -17708.184 | AC24: =-Supuestos!B20*Supuestos!B24*0.032432 -> -15178.176 | AD24: =-Supuestos!B20*Supuestos!B24*0.032432 -> -15178.176 | AE24: =-Supuestos!B20*Supuestos!B24*0.032432 -> -15178.176 | AF24: =-Supuestos!B20*Supuestos!B24*0.027027 -> -12648.636 | AG24: =-Supuestos!B20*Supuestos!B24*0.027027 -> -12648.636 | AH24: =-Supuestos!B20*Supuestos!B24*0.027027 -> -12648.636 | AI24: =-Supuestos!B20*Supuestos!B24*0.027027 -> -12648.636 | AJ24: =-Supuestos!B20*Supuestos!B24*0.021622 -> -10119.096 | AK24: =-Supuestos!B20*Supuestos!B24*0.021622 -> -10119.096 | AL24: =-Supuestos!B20*Supuestos!B24*0.016216 -> -7589.088 | AM24: =-Supuestos!B20*Supuestos!B24*0.016216 -> -7589.088 | AN24: =-Supuestos!B20*Supuestos!B24*0.010811 -> -5059.548 | AO24: 0 | AP24: 0 | AQ24: 0 | AR24: 0 | AS24: 0 | AT24: 0 | AU24: =SUM(C24:AT24) -> -468000
A25: SUBTOTAL EGRESOS DE CONSTRUCCIÓN | B25: USD | C25: =SUM(C20:C24) -> -8775 | D25: =SUM(D20:D24) -> -8775 | E25: =SUM(E20:E24) -> -8775 | F25: =SUM(F20:F24) -> -8775 | G25: =SUM(G20:G24) -> -57525 | H25: =SUM(H20:H24) -> -8775 | I25: =SUM(I20:I24) -> -8775 | J25: =SUM(J20:J24) -> -8775 | ... AT25: =SUM(AT20:AT24) -> 0 | AU25: =SUM(C25:AT25) -> -4855500
A26: D. EGRESOS — MARKETING, VENTAS Y COMERCIALIZACIÓN
A27: D1. Marketing digital — campaña total del proyecto | B27: USD | C27: =-Supuestos!B49*0.5/8 -> -5000 | D27: =-Supuestos!B49*0.5/8 -> -5000 | E27: =-Supuestos!B49*0.5/8 -> -5000 | F27: =-Supuestos!B49*0.5/8 -> -5000 | G27: =-Supuestos!B49*0.5/8 -> -5000 | H27: =-Supuestos!B49*0.5/8 -> -5000 | I27: =-Supuestos!B49*0.5/8 -> -5000 | J27: =-Supuestos!B49*0.5/8 -> -5000 | K27: =-Supuestos!B49*0.35/12 -> -2333.3333 | L27: =-Supuestos!B49*0.35/12 -> -2333.3333 | M27: =-Supuestos!B49*0.35/12 -> -2333.3333 | N27: =-Supuestos!B49*0.35/12 -> -2333.3333 | O27: =-Supuestos!B49*0.35/12 -> -2333.3333 | P27: =-Supuestos!B49*0.35/12 -> -2333.3333 | Q27: =-Supuestos!B49*0.35/12 -> -2333.3333 | R27: =-Supuestos!B49*0.35/12 -> -2333.3333 | S27: =-Supuestos!B49*0.35/12 -> -2333.3333 | T27: =-Supuestos!B49*0.35/12 -> -2333.3333 | U27: =-Supuestos!B49*0.35/12 -> -2333.3333 | V27: =-Supuestos!B49*0.35/12 -> -2333.3333 | W27: =-Supuestos!B49*0.15/18 -> -666.66667 | X27: =-Supuestos!B49*0.15/18 -> -666.66667 | Y27: =-Supuestos!B49*0.15/18 -> -666.66667 | Z27: =-Supuestos!B49*0.15/18 -> -666.66667 | AA27: =-Supuestos!B49*0.15/18 -> -666.66667 | AB27: =-Supuestos!B49*0.15/18 -> -666.66667 | AC27: =-Supuestos!B49*0.15/18 -> -666.66667 | AD27: =-Supuestos!B49*0.15/18 -> -666.66667 | AE27: =-Supuestos!B49*0.15/18 -> -666.66667 | AF27: =-Supuestos!B49*0.15/18 -> -666.66667 | AG27: =-Supuestos!B49*0.15/18 -> -666.66667 | AH27: =-Supuestos!B49*0.15/18 -> -666.66667 | AI27: =-Supuestos!B49*0.15/18 -> -666.66667 | AJ27: =-Supuestos!B49*0.15/18 -> -666.66667 | AK27: =-Supuestos!B49*0.15/18 -> -666.66667 | AL27: =-Supuestos!B49*0.15/18 -> -666.66667 | AM27: =-Supuestos!B49*0.15/18 -> -666.66667 | AN27: =-Supuestos!B49*0.15/18 -> -666.66667 | AO27: 0 | AP27: 0 | AQ27: 0 | AR27: 0 | AS27: 0 | AT27: 0 | AU27: =SUM(C27:AT27) -> -80000
A28: D2. Showroom, renders, maqueta y materiales de venta | B28: USD | C28: =-Supuestos!B50*0.7 -> -24500 | D28: =-Supuestos!B50*0.2 -> -7000 | E28: =-Supuestos!B50*0.1 -> -3500 | F28: 0 | G28: 0 | H28: 0 | I28: 0 | J28: 0 | K28: 0 | L28: 0 | M28: 0 | N28: 0 | O28: 0 | P28: 0 | Q28: 0 | R28: 0 | S28: 0 | T28: 0 | U28: 0 | V28: 0 | W28: 0 | X28: 0 | Y28: 0 | Z28: 0 | AA28: 0 | AB28: 0 | AC28: 0 | AD28: 0 | AE28: 0 | AF28: 0 | AG28: 0 | AH28: 0 | AI28: 0 | AJ28: 0 | AK28: 0 | AL28: 0 | AM28: 0 | AN28: 0 | AO28: 0 | AP28: 0 | AQ28: 0 | AR28: 0 | AS28: 0 | AT28: 0 | AU28: =SUM(C28:AT28) -> -35000
A29: D3. Eventos de lanzamiento y relaciones públicas | B29: USD | C29: 0 | D29: =-Supuestos!B51*0.5 -> -7500 | E29: 0 | F29: 0 | G29: 0 | H29: 0 | I29: 0 | J29: 0 | K29: =-Supuestos!B51*0.25 -> -3750 | L29: 0 | M29: 0 | N29: 0 | O29: 0 | P29: 0 | Q29: 0 | R29: 0 | S29: 0 | T29: 0 | U29: 0 | V29: 0 | W29: 0 | X29: 0 | Y29: 0 | Z29: 0 | AA29: 0 | AB29: 0 | AC29: 0 | AD29: 0 | AE29: 0 | AF29: 0 | AG29: 0 | AH29: 0 | AI29: 0 | AJ29: 0 | AK29: 0 | AL29: 0 | AM29: 0 | AN29: =-Supuestos!B51*0.25 -> -3750 | AO29: 0 | AP29: 0 | AQ29: 0 | AR29: 0 | AS29: 0 | AT29: 0 | AU29: =SUM(C29:AT29) -> -15000
A30: D4. Comisiones equipo interno (% sobre precio de venta) | B30: USD | C30: =-(Supuestos!B37/8)*Supuestos!B10*Supuestos!B34*Supuestos!B46*Supuestos!B48 -> -4446 | D30: =-(Supuestos!B37/8)*Supuestos!B10*Supuestos!B34*Supuestos!B46*Supuestos!B48 -> -4446 | E30: =-(Supuestos!B37/8)*Supuestos!B10*Supuestos!B34*Supuestos!B46*Supuestos!B48 -> -4446 | F30: =-(Supuestos!B37/8)*Supuestos!B10*Supuestos!B34*Supuestos!B46*Supuestos!B48 -> -4446 | G30: =-(Supuestos!B37/8)*Supuestos!B10*Supuestos!B34*Supuestos!B46*Supuestos!B48 -> -4446 | H30: =-(Supuestos!B37/8)*Supuestos!B10*Supuestos!B34*Supuestos!B46*Supuestos!B48 -> -4446 | I30: =-(Supuestos!B37/8)*Supuestos!B10*Supuestos!B34*Supuestos!B46*Supuestos!B48 -> -4446 | J30: =-(Supuestos!B37/8)*Supuestos!B10*Supuestos!B34*Supuestos!B46*Supuestos!B48 -> -4446 | K30: =-(Supuestos!B38/30)*Supuestos!B10*Supuestos!B35*Supuestos!B46*Supuestos!B48 -> -2870.4 | L30: =-(Supuestos!B38/30)*Supuestos!B10*Supuestos!B35*Supuestos!B46*Supuestos!B48 -> -2870.4 | M30: =-(Supuestos!B38/30)*Supuestos!B10*Supuestos!B35*Supuestos!B46*Supuestos!B48 -> -2870.4 | N30: =-(Supuestos!B38/30)*Supuestos!B10*Supuestos!B35*Supuestos!B46*Supuestos!B48 -> -2870.4 | O30: =-(Supuestos!B38/30)*Supuestos!B10*Supuestos!B35*Supuestos!B46*Supuestos!B48 -> -2870.4 | P30: =-(Supuestos!B38/30)*Supuestos!B10*Supuestos!B35*Supuestos!B46*Supuestos!B48 -> -2870.4 | Q30: =-(Supuestos!B38/30)*Supuestos!B10*Supuestos!B35*Supuestos!B46*Supuestos!B48 -> -2870.4 | R30: =-(Supuestos!B38/30)*Supuestos!B10*Supuestos!B35*Supuestos!B46*Supuestos!B48 -> -2870.4 | S30: =-(Supuestos!B38/30)*Supuestos!B10*Supuestos!B35*Supuestos!B46*Supuestos!B48 -> -2870.4 | T30: =-(Supuestos!B38/30)*Supuestos!B10*Supuestos!B35*Supuestos!B46*Supuestos!B48 -> -2870.4 | U30: =-(Supuestos!B38/30)*Supuestos!B10*Supuestos!B35*Supuestos!B46*Supuestos!B48 -> -2870.4 | V30: =-(Supuestos!B38/30)*Supuestos!B10*Supuestos!B35*Supuestos!B46*Supuestos!B48 -> -2870.4 | W30: =-(Supuestos!B38/30)*Supuestos!B10*Supuestos!B35*Supuestos!B46*Supuestos!B48 -> -2870.4 | X30: =-(Supuestos!B38/30)*Supuestos!B10*Supuestos!B35*Supuestos!B46*Supuestos!B48 -> -2870.4 | Y30: =-(Supuestos!B38/30)*Supuestos!B10*Supuestos!B35*Supuestos!B46*Supuestos!B48 -> -2870.4 | Z30: =-(Supuestos!B38/30)*Supuestos!B10*Supuestos!B35*Supuestos!B46*Supuestos!B48 -> -2870.4 | AA30: =-(Supuestos!B38/30)*Supuestos!B10*Supuestos!B35*Supuestos!B46*Supuestos!B48 -> -2870.4 | AB30: =-(Supuestos!B38/30)*Supuestos!B10*Supuestos!B35*Supuestos!B46*Supuestos!B48 -> -2870.4 | AC30: =-(Supuestos!B38/30)*Supuestos!B10*Supuestos!B35*Supuestos!B46*Supuestos!B48 -> -2870.4 | AD30: =-(Supuestos!B38/30)*Supuestos!B10*Supuestos!B35*Supuestos!B46*Supuestos!B48 -> -2870.4 | AE30: =-(Supuestos!B38/30)*Supuestos!B10*Supuestos!B35*Supuestos!B46*Supuestos!B48 -> -2870.4 | AF30: =-(Supuestos!B38/30)*Supuestos!B10*Supuestos!B35*Supuestos!B46*Supuestos!B48 -> -2870.4 | AG30: =-(Supuestos!B38/30)*Supuestos!B10*Supuestos!B35*Supuestos!B46*Supuestos!B48 -> -2870.4 | AH30: =-(Supuestos!B38/30)*Supuestos!B10*Supuestos!B35*Supuestos!B46*Supuestos!B48 -> -2870.4 | AI30: =-(Supuestos!B38/30)*Supuestos!B10*Supuestos!B35*Supuestos!B46*Supuestos!B48 -> -2870.4 | AJ30: =-(Supuestos!B38/30)*Supuestos!B10*Supuestos!B35*Supuestos!B46*Supuestos!B48 -> -2870.4 | AK30: =-(Supuestos!B38/30)*Supuestos!B10*Supuestos!B35*Supuestos!B46*Supuestos!B48 -> -2870.4 | AL30: =-(Supuestos!B38/30)*Supuestos!B10*Supuestos!B35*Supuestos!B46*Supuestos!B48 -> -2870.4 | AM30: =-(Supuestos!B38/30)*Supuestos!B10*Supuestos!B35*Supuestos!B46*Supuestos!B48 -> -2870.4 | AN30: =-(Supuestos!B38/30)*Supuestos!B10*Supuestos!B35*Supuestos!B46*Supuestos!B48 -> -2870.4 | AO30: =-(Supuestos!B39/3)*Supuestos!B10*Supuestos!B36*Supuestos!B46*Supuestos!B48 -> -5408 | AP30: =-(Supuestos!B39/3)*Supuestos!B10*Supuestos!B36*Supuestos!B46*Supuestos!B48 -> -5408 | AQ30: =-(Supuestos!B39/3)*Supuestos!B10*Supuestos!B36*Supuestos!B46*Supuestos!B48 -> -5408 | AR30: 0 | AS30: 0 | AT30: 0 | AU30: =SUM(C30:AT30) -> -137904
A31: D5. Comisiones red de brokers y franquicias (canal externo) | B31: USD | C31: =-(Supuestos!B37/8)*Supuestos!B10*Supuestos!B34*Supuestos!B47*(1-Supuestos!B48) -> -11115 | D31: =-(Supuestos!B37/8)*Supuestos!B10*Supuestos!B34*Supuestos!B47*(1-Supuestos!B48) -> -11115 | E31: =-(Supuestos!B37/8)*Supuestos!B10*Supuestos!B34*Supuestos!B47*(1-Supuestos!B48) -> -11115 | F31: =-(Supuestos!B37/8)*Supuestos!B10*Supuestos!B34*Supuestos!B47*(1-Supuestos!B48) -> -11115 | G31: =-(Supuestos!B37/8)*Supuestos!B10*Supuestos!B34*Supuestos!B47*(1-Supuestos!B48) -> -11115 | H31: =-(Supuestos!B37/8)*Supuestos!B10*Supuestos!B34*Supuestos!B47*(1-Supuestos!B48) -> -11115 | I31: =-(Supuestos!B37/8)*Supuestos!B10*Supuestos!B34*Supuestos!B47*(1-Supuestos!B48) -> -11115 | J31: =-(Supuestos!B37/8)*Supuestos!B10*Supuestos!B34*Supuestos!B47*(1-Supuestos!B48) -> -11115 | K31: =-(Supuestos!B38/30)*Supuestos!B10*Supuestos!B35*Supuestos!B47*(1-Supuestos!B48) -> -7176 | L31: =-(Supuestos!B38/30)*Supuestos!B10*Supuestos!B35*Supuestos!B47*(1-Supuestos!B48) -> -7176 | M31: =-(Supuestos!B38/30)*Supuestos!B10*Supuestos!B35*Supuestos!B47*(1-Supuestos!B48) -> -7176 | N31: =-(Supuestos!B38/30)*Supuestos!B10*Supuestos!B35*Supuestos!B47*(1-Supuestos!B48) -> -7176 | O31: =-(Supuestos!B38/30)*Supuestos!B10*Supuestos!B35*Supuestos!B47*(1-Supuestos!B48) -> -7176 | P31: =-(Supuestos!B38/30)*Supuestos!B10*Supuestos!B35*Supuestos!B47*(1-Supuestos!B48) -> -7176 | Q31: =-(Supuestos!B38/30)*Supuestos!B10*Supuestos!B35*Supuestos!B47*(1-Supuestos!B48) -> -7176 | R31: =-(Supuestos!B38/30)*Supuestos!B10*Supuestos!B35*Supuestos!B47*(1-Supuestos!B48) -> -7176 | S31: =-(Supuestos!B38/30)*Supuestos!B10*Supuestos!B35*Supuestos!B47*(1-Supuestos!B48) -> -7176 | T31: =-(Supuestos!B38/30)*Supuestos!B10*Supuestos!B35*Supuestos!B47*(1-Supuestos!B48) -> -7176 | U31: =-(Supuestos!B38/30)*Supuestos!B10*Supuestos!B35*Supuestos!B47*(1-Supuestos!B48) -> -7176 | V31: =-(Supuestos!B38/30)*Supuestos!B10*Supuestos!B35*Supuestos!B47*(1-Supuestos!B48) -> -7176 | W31: =-(Supuestos!B38/30)*Supuestos!B10*Supuestos!B35*Supuestos!B47*(1-Supuestos!B48) -> -7176 | X31: =-(Supuestos!B38/30)*Supuestos!B10*Supuestos!B35*Supuestos!B47*(1-Supuestos!B48) -> -7176 | Y31: =-(Supuestos!B38/30)*Supuestos!B10*Supuestos!B35*Supuestos!B47*(1-Supuestos!B48) -> -7176 | Z31: =-(Supuestos!B38/30)*Supuestos!B10*Supuestos!B35*Supuestos!B47*(1-Supuestos!B48) -> -7176 | AA31: =-(Supuestos!B38/30)*Supuestos!B10*Supuestos!B35*Supuestos!B47*(1-Supuestos!B48) -> -7176 | AB31: =-(Supuestos!B38/30)*Supuestos!B10*Supuestos!B35*Supuestos!B47*(1-Supuestos!B48) -> -7176 | AC31: =-(Supuestos!B38/30)*Supuestos!B10*Supuestos!B35*Supuestos!B47*(1-Supuestos!B48) -> -7176 | AD31: =-(Supuestos!B38/30)*Supuestos!B10*Supuestos!B35*Supuestos!B47*(1-Supuestos!B48) -> -7176 | AE31: =-(Supuestos!B38/30)*Supuestos!B10*Supuestos!B35*Supuestos!B47*(1-Supuestos!B48) -> -7176 | AF31: =-(Supuestos!B38/30)*Supuestos!B10*Supuestos!B35*Supuestos!B47*(1-Supuestos!B48) -> -7176 | AG31: =-(Supuestos!B38/30)*Supuestos!B10*Supuestos!B35*Supuestos!B47*(1-Supuestos!B48) -> -7176 | AH31: =-(Supuestos!B38/30)*Supuestos!B10*Supuestos!B35*Supuestos!B47*(1-Supuestos!B48) -> -7176 | AI31: =-(Supuestos!B38/30)*Supuestos!B10*Supuestos!B35*Supuestos!B47*(1-Supuestos!B48) -> -7176 | AJ31: =-(Supuestos!B38/30)*Supuestos!B10*Supuestos!B35*Supuestos!B47*(1-Supuestos!B48) -> -7176 | AK31: =-(Supuestos!B38/30)*Supuestos!B10*Supuestos!B35*Supuestos!B47*(1-Supuestos!B48) -> -7176 | AL31: =-(Supuestos!B38/30)*Supuestos!B10*Supuestos!B35*Supuestos!B47*(1-Supuestos!B48) -> -7176 | AM31: =-(Supuestos!B38/30)*Supuestos!B10*Supuestos!B35*Supuestos!B47*(1-Supuestos!B48) -> -7176 | AN31: =-(Supuestos!B38/30)*Supuestos!B10*Supuestos!B35*Supuestos!B47*(1-Supuestos!B48) -> -7176 | AO31: =-(Supuestos!B39/3)*Supuestos!B10*Supuestos!B36*Supuestos!B47*(1-Supuestos!B48) -> -13520 | AP31: =-(Supuestos!B39/3)*Supuestos!B10*Supuestos!B36*Supuestos!B47*(1-Supuestos!B48) -> -13520 | AQ31: =-(Supuestos!B39/3)*Supuestos!B10*Supuestos!B36*Supuestos!B47*(1-Supuestos!B48) -> -13520 | AR31: 0 | AS31: 0 | AT31: 0 | AU31: =SUM(C31:AT31) -> -344760
A32: SUBTOTAL EGRESOS MARKETING Y VENTAS | B32: USD | C32: =SUM(C27:C31) -> -45061 | D32: =SUM(D27:D31) -> -35061 | E32: =SUM(E27:E31) -> -24061 | F32: =SUM(F27:F31) -> -20561 | G32: =SUM(G27:G31) -> -20561 | H32: =SUM(H27:H31) -> -20561 | I32: =SUM(I27:I31) -> -20561 | J32: =SUM(J27:J31) -> -20561 | ... AT32: =SUM(AT27:AT31) -> 0 | AU32: =SUM(C32:AT32) -> -612664
A33: E. EGRESOS — FINANCIEROS, LEGALES Y ADMINISTRATIVOS
A34: E1. Honorarios del fiduciario (fee anual sobre activos) | B34: USD | C34: =-(Supuestos!B14+Supuestos!B20)*Supuestos!B55/12 -> -1833.3333 | D34: =-(Supuestos!B14+Supuestos!B20)*Supuestos!B55/12 -> -1833.3333 | E34: =-(Supuestos!B14+Supuestos!B20)*Supuestos!B55/12 -> -1833.3333 | F34: =-(Supuestos!B14+Supuestos!B20)*Supuestos!B55/12 -> -1833.3333 | G34: =-(Supuestos!B14+Supuestos!B20)*Supuestos!B55/12 -> -1833.3333 | H34: =-(Supuestos!B14+Supuestos!B20)*Supuestos!B55/12 -> -1833.3333 | I34: =-(Supuestos!B14+Supuestos!B20)*Supuestos!B55/12 -> -1833.3333 | J34: =-(Supuestos!B14+Supuestos!B20)*Supuestos!B55/12 -> -1833.3333 | K34: =-(Supuestos!B14+Supuestos!B20)*Supuestos!B55/12 -> -1833.3333 | L34: =-(Supuestos!B14+Supuestos!B20)*Supuestos!B55/12 -> -1833.3333 | M34: =-(Supuestos!B14+Supuestos!B20)*Supuestos!B55/12 -> -1833.3333 | N34: =-(Supuestos!B14+Supuestos!B20)*Supuestos!B55/12 -> -1833.3333 | O34: =-(Supuestos!B14+Supuestos!B20)*Supuestos!B55/12 -> -1833.3333 | P34: =-(Supuestos!B14+Supuestos!B20)*Supuestos!B55/12 -> -1833.3333 | Q34: =-(Supuestos!B14+Supuestos!B20)*Supuestos!B55/12 -> -1833.3333 | R34: =-(Supuestos!B14+Supuestos!B20)*Supuestos!B55/12 -> -1833.3333 | S34: =-(Supuestos!B14+Supuestos!B20)*Supuestos!B55/12 -> -1833.3333 | T34: =-(Supuestos!B14+Supuestos!B20)*Supuestos!B55/12 -> -1833.3333 | U34: =-(Supuestos!B14+Supuestos!B20)*Supuestos!B55/12 -> -1833.3333 | V34: =-(Supuestos!B14+Supuestos!B20)*Supuestos!B55/12 -> -1833.3333 | W34: =-(Supuestos!B14+Supuestos!B20)*Supuestos!B55/12 -> -1833.3333 | X34: =-(Supuestos!B14+Supuestos!B20)*Supuestos!B55/12 -> -1833.3333 | Y34: =-(Supuestos!B14+Supuestos!B20)*Supuestos!B55/12 -> -1833.3333 | Z34: =-(Supuestos!B14+Supuestos!B20)*Supuestos!B55/12 -> -1833.3333 | AA34: =-(Supuestos!B14+Supuestos!B20)*Supuestos!B55/12 -> -1833.3333 | AB34: =-(Supuestos!B14+Supuestos!B20)*Supuestos!B55/12 -> -1833.3333 | AC34: =-(Supuestos!B14+Supuestos!B20)*Supuestos!B55/12 -> -1833.3333 | AD34: =-(Supuestos!B14+Supuestos!B20)*Supuestos!B55/12 -> -1833.3333 | AE34: =-(Supuestos!B14+Supuestos!B20)*Supuestos!B55/12 -> -1833.3333 | AF34: =-(Supuestos!B14+Supuestos!B20)*Supuestos!B55/12 -> -1833.3333 | AG34: =-(Supuestos!B14+Supuestos!B20)*Supuestos!B55/12 -> -1833.3333 | AH34: =-(Supuestos!B14+Supuestos!B20)*Supuestos!B55/12 -> -1833.3333 | AI34: =-(Supuestos!B14+Supuestos!B20)*Supuestos!B55/12 -> -1833.3333 | AJ34: =-(Supuestos!B14+Supuestos!B20)*Supuestos!B55/12 -> -1833.3333 | AK34: =-(Supuestos!B14+Supuestos!B20)*Supuestos!B55/12 -> -1833.3333 | AL34: =-(Supuestos!B14+Supuestos!B20)*Supuestos!B55/12 -> -1833.3333 | AM34: =-(Supuestos!B14+Supuestos!B20)*Supuestos!B55/12 -> -1833.3333 | AN34: =-(Supuestos!B14+Supuestos!B20)*Supuestos!B55/12 -> -1833.3333 | AO34: =-(Supuestos!B14+Supuestos!B20)*Supuestos!B55/12 -> -1833.3333 | AP34: =-(Supuestos!B14+Supuestos!B20)*Supuestos!B55/12 -> -1833.3333 | AQ34: =-(Supuestos!B14+Supuestos!B20)*Supuestos!B55/12 -> -1833.3333 | AR34: =-(Supuestos!B14+Supuestos!B20)*Supuestos!B55/12 -> -1833.3333 | AS34: =-(Supuestos!B14+Supuestos!B20)*Supuestos!B55/12 -> -1833.3333 | AT34: =-(Supuestos!B14+Supuestos!B20)*Supuestos!B55/12 -> -1833.3333 | AU34: =SUM(C34:AT34) -> -80666.667
A35: E2. Gastos legales y notariales — escrituración | B35: USD | C35: 0 | D35: 0 | E35: 0 | F35: 0 | G35: 0 | H35: 0 | I35: 0 | J35: 0 | K35: 0 | L35: 0 | M35: 0 | N35: 0 | O35: 0 | P35: 0 | Q35: 0 | R35: 0 | S35: 0 | T35: 0 | U35: 0 | V35: 0 | W35: 0 | X35: 0 | Y35: 0 | Z35: 0 | AA35: 0 | AB35: 0 | AC35: 0 | AD35: 0 | AE35: 0 | AF35: 0 | AG35: 0 | AH35: 0 | AI35: 0 | AJ35: 0 | AK35: 0 | AL35: 0 | AM35: 0 | AN35: 0 | AO35: =-(Supuestos!B9/5)*Supuestos!B56 -> -24000 | AP35: =-(Supuestos!B9/5)*Supuestos!B56 -> -24000 | AQ35: =-(Supuestos!B9/5)*Supuestos!B56 -> -24000 | AR35: =-(Supuestos!B9/5)*Supuestos!B56 -> -24000 | AS35: =-(Supuestos!B9/5)*Supuestos!B56 -> -24000 | AT35: 0 | AU35: =SUM(C35:AT35) -> -120000
A36: E3. Impuesto de sellos sobre operaciones | B36: USD | C36: =-(Supuestos!B37/8)*Supuestos!B10*Supuestos!B34*Supuestos!B57 -> -6669 | D36: =-(Supuestos!B37/8)*Supuestos!B10*Supuestos!B34*Supuestos!B57 -> -6669 | E36: =-(Supuestos!B37/8)*Supuestos!B10*Supuestos!B34*Supuestos!B57 -> -6669 | F36: =-(Supuestos!B37/8)*Supuestos!B10*Supuestos!B34*Supuestos!B57 -> -6669 | G36: =-(Supuestos!B37/8)*Supuestos!B10*Supuestos!B34*Supuestos!B57 -> -6669 | H36: =-(Supuestos!B37/8)*Supuestos!B10*Supuestos!B34*Supuestos!B57 -> -6669 | I36: =-(Supuestos!B37/8)*Supuestos!B10*Supuestos!B34*Supuestos!B57 -> -6669 | J36: =-(Supuestos!B37/8)*Supuestos!B10*Supuestos!B34*Supuestos!B57 -> -6669 | K36: =-(Supuestos!B38/30)*Supuestos!B10*Supuestos!B35*Supuestos!B57 -> -4305.6 | L36: =-(Supuestos!B38/30)*Supuestos!B10*Supuestos!B35*Supuestos!B57 -> -4305.6 | M36: =-(Supuestos!B38/30)*Supuestos!B10*Supuestos!B35*Supuestos!B57 -> -4305.6 | N36: =-(Supuestos!B38/30)*Supuestos!B10*Supuestos!B35*Supuestos!B57 -> -4305.6 | O36: =-(Supuestos!B38/30)*Supuestos!B10*Supuestos!B35*Supuestos!B57 -> -4305.6 | P36: =-(Supuestos!B38/30)*Supuestos!B10*Supuestos!B35*Supuestos!B57 -> -4305.6 | Q36: =-(Supuestos!B38/30)*Supuestos!B10*Supuestos!B35*Supuestos!B57 -> -4305.6 | R36: =-(Supuestos!B38/30)*Supuestos!B10*Supuestos!B35*Supuestos!B57 -> -4305.6 | S36: =-(Supuestos!B38/30)*Supuestos!B10*Supuestos!B35*Supuestos!B57 -> -4305.6 | T36: =-(Supuestos!B38/30)*Supuestos!B10*Supuestos!B35*Supuestos!B57 -> -4305.6 | U36: =-(Supuestos!B38/30)*Supuestos!B10*Supuestos!B35*Supuestos!B57 -> -4305.6 | V36: =-(Supuestos!B38/30)*Supuestos!B10*Supuestos!B35*Supuestos!B57 -> -4305.6 | W36: =-(Supuestos!B38/30)*Supuestos!B10*Supuestos!B35*Supuestos!B57 -> -4305.6 | X36: =-(Supuestos!B38/30)*Supuestos!B10*Supuestos!B35*Supuestos!B57 -> -4305.6 | Y36: =-(Supuestos!B38/30)*Supuestos!B10*Supuestos!B35*Supuestos!B57 -> -4305.6 | Z36: =-(Supuestos!B38/30)*Supuestos!B10*Supuestos!B35*Supuestos!B57 -> -4305.6 | AA36: =-(Supuestos!B38/30)*Supuestos!B10*Supuestos!B35*Supuestos!B57 -> -4305.6 | AB36: =-(Supuestos!B38/30)*Supuestos!B10*Supuestos!B35*Supuestos!B57 -> -4305.6 | AC36: =-(Supuestos!B38/30)*Supuestos!B10*Supuestos!B35*Supuestos!B57 -> -4305.6 | AD36: =-(Supuestos!B38/30)*Supuestos!B10*Supuestos!B35*Supuestos!B57 -> -4305.6 | AE36: =-(Supuestos!B38/30)*Supuestos!B10*Supuestos!B35*Supuestos!B57 -> -4305.6 | AF36: =-(Supuestos!B38/30)*Supuestos!B10*Supuestos!B35*Supuestos!B57 -> -4305.6 | AG36: =-(Supuestos!B38/30)*Supuestos!B10*Supuestos!B35*Supuestos!B57 -> -4305.6 | AH36: =-(Supuestos!B38/30)*Supuestos!B10*Supuestos!B35*Supuestos!B57 -> -4305.6 | AI36: =-(Supuestos!B38/30)*Supuestos!B10*Supuestos!B35*Supuestos!B57 -> -4305.6 | AJ36: =-(Supuestos!B38/30)*Supuestos!B10*Supuestos!B35*Supuestos!B57 -> -4305.6 | AK36: =-(Supuestos!B38/30)*Supuestos!B10*Supuestos!B35*Supuestos!B57 -> -4305.6 | AL36: =-(Supuestos!B38/30)*Supuestos!B10*Supuestos!B35*Supuestos!B57 -> -4305.6 | AM36: =-(Supuestos!B38/30)*Supuestos!B10*Supuestos!B35*Supuestos!B57 -> -4305.6 | AN36: =-(Supuestos!B38/30)*Supuestos!B10*Supuestos!B35*Supuestos!B57 -> -4305.6 | AO36: =-(Supuestos!B39/5)*Supuestos!B10*Supuestos!B36*Supuestos!B57 -> -4867.2 | AP36: =-(Supuestos!B39/5)*Supuestos!B10*Supuestos!B36*Supuestos!B57 -> -4867.2 | AQ36: =-(Supuestos!B39/5)*Supuestos!B10*Supuestos!B36*Supuestos!B57 -> -4867.2 | AR36: =-(Supuestos!B39/5)*Supuestos!B10*Supuestos!B36*Supuestos!B57 -> -4867.2 | AS36: =-(Supuestos!B39/5)*Supuestos!B10*Supuestos!B36*Supuestos!B57 -> -4867.2 | AT36: 0 | AU36: =SUM(C36:AT36) -> -206856
A37: E4. Gastos administrativos del proyecto (mensual) | B37: USD | C37: =-Supuestos!B59 -> -8000 | D37: =-Supuestos!B59 -> -8000 | E37: =-Supuestos!B59 -> -8000 | F37: =-Supuestos!B59 -> -8000 | G37: =-Supuestos!B59 -> -8000 | H37: =-Supuestos!B59 -> -8000 | I37: =-Supuestos!B59 -> -8000 | J37: =-Supuestos!B59 -> -8000 | K37: =-Supuestos!B59 -> -8000 | L37: =-Supuestos!B59 -> -8000 | M37: =-Supuestos!B59 -> -8000 | N37: =-Supuestos!B59 -> -8000 | O37: =-Supuestos!B59 -> -8000 | P37: =-Supuestos!B59 -> -8000 | Q37: =-Supuestos!B59 -> -8000 | R37: =-Supuestos!B59 -> -8000 | S37: =-Supuestos!B59 -> -8000 | T37: =-Supuestos!B59 -> -8000 | U37: =-Supuestos!B59 -> -8000 | V37: =-Supuestos!B59 -> -8000 | W37: =-Supuestos!B59 -> -8000 | X37: =-Supuestos!B59 -> -8000 | Y37: =-Supuestos!B59 -> -8000 | Z37: =-Supuestos!B59 -> -8000 | AA37: =-Supuestos!B59 -> -8000 | AB37: =-Supuestos!B59 -> -8000 | AC37: =-Supuestos!B59 -> -8000 | AD37: =-Supuestos!B59 -> -8000 | AE37: =-Supuestos!B59 -> -8000 | AF37: =-Supuestos!B59 -> -8000 | AG37: =-Supuestos!B59 -> -8000 | AH37: =-Supuestos!B59 -> -8000 | AI37: =-Supuestos!B59 -> -8000 | AJ37: =-Supuestos!B59 -> -8000 | AK37: =-Supuestos!B59 -> -8000 | AL37: =-Supuestos!B59 -> -8000 | AM37: =-Supuestos!B59 -> -8000 | AN37: =-Supuestos!B59 -> -8000 | AO37: =-Supuestos!B59 -> -8000 | AP37: =-Supuestos!B59 -> -8000 | AQ37: =-Supuestos!B59 -> -8000 | AR37: =-Supuestos!B59 -> -8000 | AS37: =-Supuestos!B59 -> -8000 | AT37: =-Supuestos!B59 -> -8000 | AU37: =SUM(C37:AT37) -> -352000
A38: E5. Gastos adicionales de escrituración (registros, certificados) | B38: USD | C38: 0 | D38: 0 | E38: 0 | F38: 0 | G38: 0 | H38: 0 | I38: 0 | J38: 0 | K38: 0 | L38: 0 | M38: 0 | N38: 0 | O38: 0 | P38: 0 | Q38: 0 | R38: 0 | S38: 0 | T38: 0 | U38: 0 | V38: 0 | W38: 0 | X38: 0 | Y38: 0 | Z38: 0 | AA38: 0 | AB38: 0 | AC38: 0 | AD38: 0 | AE38: 0 | AF38: 0 | AG38: 0 | AH38: 0 | AI38: 0 | AJ38: 0 | AK38: 0 | AL38: 0 | AM38: 0 | AN38: 0 | AO38: =-((Supuestos!B37+Supuestos!B38+Supuestos!B39)/5)*Supuestos!B10*Supuestos!B35*Supuestos!B60 -> -19136 | AP38: =-((Supuestos!B37+Supuestos!B38+Supuestos!B39)/5)*Supuestos!B10*Supuestos!B35*Supuestos!B60 -> -19136 | AQ38: =-((Supuestos!B37+Supuestos!B38+Supuestos!B39)/5)*Supuestos!B10*Supuestos!B35*Supuestos!B60 -> -19136 | AR38: =-((Supuestos!B37+Supuestos!B38+Supuestos!B39)/5)*Supuestos!B10*Supuestos!B35*Supuestos!B60 -> -19136 | AS38: =-((Supuestos!B37+Supuestos!B38+Supuestos!B39)/5)*Supuestos!B10*Supuestos!B35*Supuestos!B60 -> -19136 | AT38: 0 | AU38: =SUM(C38:AT38) -> -95680
A39: SUBTOTAL EGRESOS FINANCIEROS Y ADMINISTRATIVOS | B39: USD | C39: =SUM(C34:C38) -> -16502.333 | D39: =SUM(D34:D38) -> -16502.333 | E39: =SUM(E34:E38) -> -16502.333 | F39: =SUM(F34:F38) -> -16502.333 | G39: =SUM(G34:G38) -> -16502.333 | H39: =SUM(H34:H38) -> -16502.333 | I39: =SUM(I34:I38) -> -16502.333 | J39: =SUM(J34:J38) -> -16502.333 | ... AT39: =SUM(AT34:AT38) -> -9833.3333 | AU39: =SUM(C39:AT39) -> -855202.67
A40: F. RETORNO A INVERSORES
...

Sheet Resumen Ejecutivo
A1: RESUMEN EJECUTIVO DEL FIDEICOMISO INMOBILIARIO
A2: Principales indicadores del proyecto — valores calculados del modelo
A4: TAMAÑO Y ESTRUCTURA DEL PROYECTO
A5: Total de unidades | B5: =Supuestos!B9 -> 80
A6: Superficie vendible total (m²) | B6: =Supuestos!B11 -> 5200
A7: Precio promedio ponderado por m² (USD) | B7: =(Supuestos!B34*Supuestos!B37+Supuestos!B35*Supuestos!B38+Supuestos!B36*Supuestos!B39)/(Supuestos!B37+Supuestos!B38+Supuestos!B39) -> 2210
A8: Ingreso bruto total proyectado (USD) | B8: ='Flujo de Fondos'!AU13 -> 5532914.4
A10: ESTRUCTURA DE COSTOS TOTALES (USD)
A11: Costo del terreno | B11: =Supuestos!B14 -> 500000
A12: Costo de construcción total (hard cost) | B12: =Supuestos!B20 -> 3900000
A13: Soft costs totales (arquitecto + permisos + gerenciamiento) | B13: =Supuestos!B20*(Supuestos!B21+Supuestos!B22+Supuestos!B23) -> 487500
A14: Contingencia de obra | B14: =Supuestos!B20*Supuestos!B24 -> 468000
A15: Marketing y ventas | B15: ='Flujo de Fondos'!AU32 -> -612664
A16: Costos financieros y administrativos | B16: ='Flujo de Fondos'!AU39 -> -855202.67
A17: Retorno total a inversores (terreno + obra) | B17: ='Flujo de Fondos'!AU46 -> -1996216.8
A19: ESTRUCTURA DE FINANCIAMIENTO (USD)
A20: Capital aportado por inversor del terreno | B20: =Supuestos!B14 -> 500000
A21: Capital aportado por inversores de obra (50%) | B21: =Supuestos!B20*Supuestos!B28 -> 1950000
A22: Capital total de inversores externos | B22: =Supuestos!B14+Supuestos!B20*Supuestos!B28 -> 2450000
A23: Financiamiento vía preventas (ingresos meses 1-8) | B23: ='Flujo de Fondos'!AU6+'Flujo de Fondos'!AU7 -> 2667600
A24: Capital propio del desarrollador (saldo de financiamiento) | B24: =ABS('Flujo de Fondos'!AU18)-Supuestos!B14 -> 7500
A26: RESULTADO Y RENTABILIDAD
A27: Resultado neto del fideicomiso (USD) | B27: ='Flujo de Fondos'!AU49 -> -3294169
A28: Margen neto sobre ventas (%) | B28: ='Flujo de Fondos'!AU49/'Flujo de Fondos'!AU13 -> -0.59537683
A29: Retorno total al inversor del terreno (capital + renta) | B29: =-'Flujo de Fondos'!AU41-'Flujo de Fondos'!AU42 -> 744431.87
A30: Retorno total a inversores de obra (capital + renta) | B30: ='Flujo de Fondos'!AU43-'Flujo de Fondos'!AU44-'Flujo de Fondos'!AU45 -> 5151784.9
A31: Excedente para el desarrollador (USD) | B31: ='Flujo de Fondos'!AU49-'Flujo de Fondos'!AU42-'Flujo de Fondos'!AU45 -> -1797952.3
A33: PLAZOS CLAVE
A34: Inicio de preventa (mes del modelo) | B34: =Supuestos!B5 -> 1
A35: Inicio de construcción (mes del modelo) | B35: =Supuestos!B6 -> 9
A36: Duración de la obra (meses) | B36: =Supuestos!B7 -> 30
A37: Mes de cierre del fideicomiso | B37: =Supuestos!B8 -> 42
A38: Duración total del proyecto (meses) | B38: =Supuestos!B8 -> 42
